Workbook

Sheet Portada

Sheet 1.1. Datos_Bloomberg
A1: TICKER | B1: AAPL US Equity | D1: MSFT US Equity | F1: NVDA US Equity | H1: AVGO US Equity | J1: ORCL US Equity | L1: CRM US Equity | N1: AMD US Equity | P1: ADBE US Equity | R1: CSCO US Equity | T1: INTC US Equity | V1: XOM US Equity | X1: CVX US Equity | Z1: EOG US Equity | AB1: COP US Equity | AD1: SLB US Equity | AF1: TRGP US Equity | AH1: OXY US Equity | AJ1: PSX US Equity | AL1: KMI US Equity | AN1: MPC US Equity | AP1: AMZN US Equity | AR1: TSLA US Equity | AT1: MCD US Equity | AV1: BKNG US Equity | AX1: HD US Equity | AZ1: LOW US Equity | BB1: EBAY US Equity | BD1: SBUX US Equity | BF1: MAR US Equity | BH1: NKE US Equity
A2: DATE | B2: PX_LAST | C2: PX_VOLUME | D2: PX_LAST | E2: PX_VOLUME | F2: PX_LAST | G2: PX_VOLUME | H2: PX_LAST | I2: PX_VOLUME | J2: PX_LAST | K2: PX_VOLUME | L2: PX_LAST | M2: PX_VOLUME | N2: PX_LAST | O2: PX_VOLUME | P2: PX_LAST | Q2: PX_VOLUME | R2: PX_LAST | S2: PX_VOLUME | T2: PX_LAST | U2: PX_VOLUME | V2: PX_LAST | W2: PX_VOLUME | X2: PX_LAST | Y2: PX_VOLUME | Z2: PX_LAST | AA2: PX_VOLUME | AB2: PX_LAST | AC2: PX_VOLUME | AD2: PX_LAST | AE2: PX_VOLUME | AF2: PX_LAST | AG2: PX_VOLUME | AH2: PX_LAST | AI2: PX_VOLUME | AJ2: PX_LAST | AK2: PX_VOLUME | AL2: PX_LAST | AM2: PX_VOLUME | AN2: PX_LAST | AO2: PX_VOLUME | AP2: PX_LAST | AQ2: PX_VOLUME | AR2: PX_LAST | AS2: PX_VOLUME | AT2: PX_LAST | AU2: PX_VOLUME | AV2: PX_LAST | AW2: PX_VOLUME | AX2: PX_LAST | AY2: PX_VOLUME | AZ2: PX_LAST | BA2: PX_VOLUME | BB2: PX_LAST | BC2: PX_VOLUME | BD2: PX_LAST | BE2: PX_VOLUME | BF2: PX_LAST | BG2: PX_VOLUME | BH2: PX_LAST | BI2: PX_VOLUME
A3: 42006 | B3: 109.33 | C3: 53204626 | D3: 46.76 | E3: 27913852 | F3: 20.13 | G3: 2842012 | H3: 100.09 | I3: 1350045 | J3: 44.33 | K3: 15070165 | L3: 59.24 | M3: 2801679 | N3: 2.69 | O3: 8330255 | P3: 72.34 | Q3: 2356405 | R3: 27.61 | S3: 22926512 | T3: 36.36 | U3: 23605607 | V3: 92.83 | W3: 10220410 | X3: 112.58 | Y3: 5907276 | Z3: 92.24 | AA3: 3463489 | AB3: 68.92 | AC3: 5701787 | AD3: 85.67 | AE3: 5500806 | AF3: 107.06 | AG3: 471239 | AH3: 80.65 | AI3: 3634610 | AJ3: 72.29 | AK3: 2545240 | AL3: 42.81 | AM3: 8662289 | AN3: 91.64 | AO3: 2679659 | AP3: 308.52 | AQ3: 2788101 | AR3: 219.31 | AS3: 4764443 | AT3: 93.26 | AU3: 6019693 | AV3: 1142.06 | AW3: 510013 | AX3: 103.43 | AY3: 4324850 | AZ3: 67.7 | BA3: 4213210 | BB3: 56.21 | BC3: 5901204 | BD3: 81.44 | BE3: 3453049 | BF3: 77.75 | BG3: 1278232 | BH3: 95.03 | BI3: 2492878
A4: 42009 | B4: 106.25 | C4: 64285491 | D4: 46.325 | E4: 39673865 | F4: 19.79 | G4: 4948799 | H4: 98.49 | I4: 1559603 | J4: 43.59 | K4: 18375801 | L4: 58.17 | M4: 3688208 | N4: 2.66 | O4: 8878176 | P4: 71.98 | Q4: 2405286 | R4: 27.06 | S4: 29460603 | T4: 35.95 | U4: 32784975 | V4: 90.29 | W4: 18502381 | X4: 108.08 | Y4: 11758103 | Z4: 86.68 | AA4: 6173633 | AB4: 65.64 | AC4: 10948884 | AD4: 83.35 | AE4: 10039424 | AF4: 99.19 | AG4: 955968 | AH4: 77.66 | AI4: 6104730 | AJ4: 67.92 | AK4: 5885961 | AL4: 41.65 | AM4: 15811108 | AN4: 89.09 | AO4: 5246379 | AP4: 302.19 | AQ4: 2774231 | AR4: 210.09 | AS4: 5368477 | AT4: 92.23 | AU4: 6211872 | AV4: 1097.58 | AW4: 1052212 | AX4: 101.26 | AY4: 5881379 | AZ4: 66.08 | BA4: 7337721 | BB4: 55.735 | BC4: 7447007 | BD4: 79.88 | BE4: 5811898 | BF4: 75.62 | BG4: 2036204 | BH4: 93.5 | BI4: 3444586
A5: 42010 | B5: 106.26 | C5: 65797116 | D5: 45.65 | E5: 36447854 | F5: 19.19 | G5: 4944121 | H5: 96.25 | I5: 2219434 | J5: 43.14 | K5: 19229461 | L5: 57.2 | M5: 3182909 | N5: 2.63 | O5: 13916645 | P5: 70.53 | Q5: 2895356 | R5: 27.05 | S5: 47297634 | T5: 35.28 | U5: 30847578 | V5: 89.81 | W5: 16670713 | X5: 108.03 | Y5: 11591591 | Z5: 84.21 | AA5: 8150001 | AB5: 62.93 | AC5: 18054690 | AD5: 81.72 | AE5: 9758355 | AF5: 96.11 | AG5: 1072840 | AH5: 77 | AI5: 6038092 | AJ5: 66.02 | AK5: 5795753 | AL5: 40.83 | AM5: 20023006 | AN5: 88.21 | AO5: 2802266 | AP5: 295.29 | AQ5: 3519034 | AR5: 211.28 | AS5: 6261936 | AT5: 92.4 | AU5: 6484094 | AV5: 1079.96 | AW5: 1082465 | AX5: 100.95 | AY5: 4913547 | AZ5: 66.23 | BA5: 5247443 | BB5: 55.02 | BC5: 9649307 | BD5: 79.23 | BE5: 3832170 | BF5: 74.67 | BG5: 2561002 | BH5: 92.95 | BI5: 3788029
A6: 42011 | B6: 107.75 | C6: 40105934 | D6: 46.23 | E6: 29114061 | F6: 19.135 | G6: 8045186 | H6: 98.85 | I6: 3090685 | J6: 43.15 | K6: 13502164 | L6: 56.93 | M6: 4284339 | N6: 2.58 | O6: 12377554 | P6: 71.11 | Q6: 2378276 | R6: 27.3 | S6: 27570801 | T6: 36.02 | U6: 27725167 | V6: 90.72 | W6: 13590721 | X6: 107.94 | Y6: 10353817 | Z6: 83.68 | AA6: 5950338 | AB6: 63.35 | AC6: 12350537 | AD6: 81.71 | AE6: 7951588 | AF6: 95.2 | AG6: 745036 | AH6: 77.01 | AI6: 5475349 | AJ6: 66.31 | AK6: 5558227 | AL6: 41.37 | AM6: 12045879 | AN6: 88.94 | AO6: 3505973 | AP6: 298.42 | AQ6: 2640349 | AR6: 210.95 | AS6: 2968390 | AT6: 94.01 | AU6: 6400320 | AV6: 1069.57 | AW6: 955020 | AX6: 104.41 | AY6: 5090980 | AZ6: 68.2 | BA6: 4719628 | BB6: 54.925 | BC6: 9251549 | BD6: 81.18 | BE6: 4866277 | BF6: 76.38 | BG6: 1979431 | BH6: 94.87 | BI6: 3628028
A7: 42012 | B7: 111.89 | C7: 59364547 | D7: 47.59 | E7: 29645202 | F7: 19.86 | G7: 7094534 | H7: 103.79 | I7: 3334923 | J7: 43.41 | K7: 17516877 | L7: 58.59 | M7: 3756594 | N7: 2.61 | O7: 11136587 | P7: 72.915 | Q7: 2624237 | R7: 27.51 | S7: 40906993 | T7: 36.69 | U7: 31765371 | V7: 92.23 | W7: 15487496 | X7: 110.41 | Y7: 8650761 | Z7: 86.88 | AA7: 5840270 | AB7: 64.93 | AC7: 10348337 | AD7: 82.7 | AE7: 7911582 | AF7: 97.89 | AG7: 833028 | AH7: 77.69 | AI7: 6734730 | AJ7: 68.89 | AK7: 5432708 | AL7: 42.34 | AM7: 15461199 | AN7: 91.03 | AO7: 3500056 | AP7: 300.46 | AQ7: 3088398 | AR7: 210.615 | AS7: 3442509 | AT7: 94.36 | AU7: 5476740 | AV7: 1082.85 | AW7: 1047522 | AX7: 106.72 | AY7: 6468184 | AZ7: 69.64 | BA7: 5541596 | BB7: 56.41 | BC7: 10238405 | BD7: 82.49 | BE7: 6585274 | BF7: 78.91 | BG7: 2396083 | BH7: 97.06 | BI7: 2998622
A8: 42013 | B8: 112.01 | C8: 53699527 | D8: 47.19 | E8: 23944181 | F8: 19.94 | G8: 5238601 | H8: 104.895 | I8: 2343240 | J8: 43.39 | K8: 15957540 | L8: 58.16 | M8: 6875336 | N8: 2.63 | O8: 8907618 | P8: 71.84 | Q8: 1730255 | R8: 27.79 | S8: 33619558 | T8: 36.76 | U8: 22850524 | V8: 92.1 | W8: 14488415 | X8: 108.21 | Y8: 9584510 | Z8: 87.46 | AA8: 4036602 | AB8: 64.92 | AC8: 7984136 | AD8: 81.22 | AE8: 7652441 | AF8: 92.82 | AG8: 831459 | AH8: 77.54 | AI8: 5203863 | AJ8: 67.31 | AK8: 4438018 | AL8: 41.81 | AM8: 10290542 | AN8: 88.49 | AO8: 2685279 | AP8: 296.93 | AQ8: 2592360 | AR8: 206.66 | AS8: 4668295 | AT8: 93.21 | AU8: 4283293 | AV8: 1051.96 | AW8: 974431 | AX8: 104.89 | AY8: 5717610 | AZ8: 68.33 | BA8: 5643963 | BB8: 55.63 | BC8: 7008771 | BD8: 79.79 | BE8: 13778353 | BF8: 78.73 | BG8: 2350882 | BH8: 95.99 | BI8: 2344460
A9: 42016 | B9: 109.25 | C9: 49650790 | D9: 46.6 | E9: 23651887 | F9: 19.69 | G9: 4768307 | H9: 103.16 | I9: 1869822 | J9: 43.27 | K9: 16055720 | L9: 57.73 | M9: 2724454 | N9: 2.63 | O9: 9979638 | P9: 71.12 | Q9: 1337867 | R9: 28.05 | S9: 38648396 | T9: 36.6 | U9: 29400781 | V9: 90.33 | W9: 15176303 | X9: 105.88 | Y9: 8912332 | Z9: 84.51 | AA9: 4810322 | AB9: 63.07 | AC9: 8317112 | AD9: 78.05 | AE9: 13257136 | AF9: 89.27 | AG9: 1032951 | AH9: 74.95 | AI9: 7127751 | AJ9: 64.24 | AK9: 5232286 | AL9: 41.61 | AM9: 12522865 | AN9: 85.42 | AO9: 4129108 | AP9: 291.41 | AQ9: 3421392 | AR9: 202.21 | AS9: 5950280 | AT9: 93.01 | AU9: 3989585 | AV9: 1039.98 | AW9: 1078485 | AX9: 104.42 | AY9: 4992945 | AZ9: 67.85 | BA9: 4604788 | BB9: 55.2 | BC9: 4541996 | BD9: 80.23 | BE9: 5010743 | BF9: 77.905 | BG9: 1715747 | BH9: 95.86 | BI9: 2815433
A10: 42017 | B10: 110.22 | C10: 67091928 | D10: 46.355 | E10: 35270601 | F10: 19.655 | G10: 5917960 | H10: 102.58 | I10: 2433701 | J10: 42.93 | K10: 12878161 | L10: 57.97 | M10: 3509124 | N10: 2.66 | O10: 17907354 | P10: 70.59 | Q10: 2103821 | R10: 28.095 | S10: 36074151 | T10: 36.5 | U10: 31477952 | V10: 90 | W10: 17469028 | X10: 104.2 | Y10: 13277742 | Z10: 85.06 | AA10: 5446131 | AB10: 62.44 | AC10: 10240869 | AD10: 77.78 | AE10: 11936635 | AF10: 85.87 | AG10: 974634 | AH10: 74.97 | AI10: 7084487 | AJ10: 61.5 | AK10: 8886398 | AL10: 40.89 | AM10: 14166540 | AN10: 80.86 | AO10: 6287556 | AP10: 294.74 | AQ10: 4136442 | AR10: 204.25 | AS10: 4477320 | AT10: 92.83 | AU10: 5971237 | AV10: 1037.82 | AW10: 871538 | AX10: 103.73 | AY10: 5395151 | AZ10: 67.86 | BA10: 6034530 | BB10: 55.13 | BC10: 6468381 | BD10: 80.87 | BE10: 5520351 | BF10: 77.42 | BG10: 2505961 | BH10: 95.01 | BI10: 3091094
A11: 42018 | B11: 109.8 | C11: 48956588 | D11: 45.955 | E11: 29719580 | F11: 19.74 | G11: 3881531 | H11: 103.39 | I11: 2098914 | J11: 43.06 | K11: 12707442 | L11: 57.25 | M11: 3098375 | N11: 2.63 | O11: 9989870 | P11: 69.99 | Q11: 1927063 | R11: 27.92 | S11: 29494443 | T11: 36.35 | U11: 34250293 | V11: 89.74 | W11: 23272056 | X11: 103.9 | Y11: 14116923 | Z11: 87.74 | AA11: 6698177 | AB11: 62.62 | AC11: 10005362 | AD11: 78.39 | AE11: 12226689 | AF11: 85.49 | AG11: 969356 | AH11: 75.48 | AI11: 7109842 | AJ11: 59.42 | AK11: 11611127 | AL11: 41.22 | AM11: 13330471 | AN11: 77.63 | AO11: 7164703 | AP11: 293.27 | AQ11: 5538666 | AR11: 192.69 | AS11: 11551855 | AT11: 91.54 | AU11: 7745521 | AV11: 1035.67 | AW11: 755708 | AX11: 102.64 | AY11: 5384438 | AZ11: 67.39 | BA11: 4810860 | BB11: 54.03 | BC11: 10080944 | BD11: 80.42 | BE11: 4647542 | BF11: 76.57 | BG11: 1902261 | BH11: 93.71 | BI11: 3375184
A12: 42019 | B12: 106.82 | C12: 60013996 | D12: 45.48 | E12: 32750779 | F12: 19.6 | G12: 4723757 | H12: 101.32 | I12: 1837314 | J12: 42.63 | K12: 13431005 | L12: 55.11 | M12: 4821002 | N12: 2.52 | O12: 17744035 | P12: 70.29 | Q12: 2839158 | R12: 27.41 | S12: 29521090 | T12: 36.19 | U12: 47181771 | V12: 88.96 | W12: 18759590 | X12: 102.67 | Y12: 9664562 | Z12: 86.53 | AA12: 4941725 | AB12: 61.41 | AC12: 9993989 | AD12: 76.63 | AE12: 10918870 | AF12: 86.63 | AG12: 902844 | AH12: 75.99 | AI12: 7271531 | AJ12: 59.09 | AK12: 5531113 | AL12: 40.77 | AM12: 10391816 | AN12: 76.85 | AO12: 4730228 | AP12: 286.95 | AQ12: 4419196 | AR12: 191.87 | AS12: 5216524 | AT12: 91.38 | AU12: 5737468 | AV12: 998.25 | AW12: 1453268 | AX12: 101.01 | AY12: 6894979 | AZ12: 66.35 | BA12: 5288250 | BB12: 53.015 | BC12: 11705090 | BD12: 79.58 | BE12: 4063301 | BF12: 76.1 | BG12: 1787308 | BH12: 92.81 | BI12: 2117475
A13: 42020 | B13: 105.99 | C13: 78513345 | D13: 46.24 | E13: 35695289 | F13: 19.96 | G13: 4537800 | H13: 103.82 | I13: 1537485 | J13: 43.51 | K13: 17786705 | L13: 56.64 | M13: 3236722 | N13: 2.39 | O13: 30192441 | P13: 71.73 | Q13: 2375295 | R13: 27.68 | S13: 26655143 | T13: 36.45 | U13: 62812193 | V13: 91.12 | W13: 17713093 | X13: 105.12 | Y13: 12604555 | Z13: 90.31 | AA13: 5483464 | AB13: 63.08 | AC13: 10031369 | AD13: 81.33 | AE13: 17587516 | AF13: 88.94 | AG13: 781340 | AH13: 78.06 | AI13: 6564058 | AJ13: 60.83 | AK13: 4978583 | AL13: 41.53 | AM13: 8760796 | AN13: 77.56 | AO13: 4567893 | AP13: 290.74 | AQ13: 3478176 | AR13: 193.07 | AS13: 3603158 | AT13: 91.49 | AU13: 6926995 | AV13: 1008.22 | AW13: 1004758 | AX13: 104.12 | AY13: 6403841 | AZ13: 67.99 | BA13: 4817245 | BB13: 53.66 | BC13: 9823604 | BD13: 80.61 | BE13: 4507751 | BF13: 75.89 | BG13: 3146475 | BH13: 92.99 | BI13: 4384999
A14: 42024 | B14: 108.72 | C14: 49899907 | D14: 46.39 | E14: 36161860 | F14: 20.02 | G14: 3507719 | H14: 104.87 | I14: 1284387 | J14: 43.9 | K14: 16308441 | L14: 57.29 | M14: 6521542 | N14: 2.24 | O14: 56713301 | P14: 71.49 | Q14: 1612038 | R14: 28.07 | S14: 33684162 | T14: 36.09 | U14: 35929420 | V14: 91.09 | W14: 16760994 | X14: 106.47 | Y14: 10406775 | Z14: 89.33 | AA14: 5969472 | AB14: 63.19 | AC14: 6890502 | AD14: 80.48 | AE14: 10948629 | AF14: 89.69 | AG14: 690272 | AH14: 78.01 | AI14: 5610811 | AJ14: 63.62 | AK14: 7995203 | AL14: 41.82 | AM14: 8786193 | AN14: 80.42 | AO14: 3723128 | AP14: 289.44 | AQ14: 3075081 | AR14: 191.93 | AS14: 4503182 | AT14: 90.8 | AU14: 6967278 | AV14: 1024.95 | AW14: 700262 | AX14: 103.25 | AY14: 5335526 | AZ14: 66.52 | BA14: 5926282 | BB14: 53.68 | BC14: 8338938 | BD14: 81.225 | BE14: 5369152 | BF14: 76.32 | BG14: 1618249 | BH14: 93.61 | BI14: 4701912
... A2768: 46022 | B2768: 271.86 | C2768: 27293639 | D2768: 483.62 | E2768: 15601554 | F2768: 186.5 | G2768: 120100484 | H2768: 346.1 | I2768: 15346052 | J2768: 194.91 | K2768: 10341453 | L2768: 264.91 | M2768: 3367930 | N2768: 214.16 | O2768: 17591581 | P2768: 349.99 | Q2768: 2116207 | R2768: 77.03 | S2768: 13570464 | T2768: 36.9 | U2768: 51524682 | V2768: 120.34 | W2768: 10559866 | X2768: 152.41 | Y2768: 4953110 | Z2768: 105.01 | AA2768: 2377453 | AB2768: 93.61 | AC2768: 3551875 | AD2768: 38.38 | AE2768: 6157199 | AF2768: 184.5 | AG2768: 658827 | AH2768: 41.12 | AI2768: 6963236 | AJ2768: 129.04 | AK2768: 1339292 | AL2768: 27.49 | AM2768: 9434268 | AN2768: 162.63 | AO2768: 1323765 | AP2768: 230.82 | AQ2768: 24383749 | AR2768: 449.72 | AS2768: 49077961 | AT2768: 305.63 | AU2768: 1903701 | AV2768: 5355.33 | AW2768: 112918 | AX2768: 344.1 | AY2768: 2317891 | AZ2768: 241.16 | BA2768: 1615256 | BB2768: 87.1 | BC2768: 3103832 | BD2768: 84.21 | BE2768: 5293385 | BF2768: 310.24 | BG2768: 1228384 | BH2768: 63.71 | BI2768: 35457432

Sheet 1.2-1.3 Pesos
A1: Sector | B1: Empresa | C1: Volumen de transaccion incial (valor del 02/01/2015) | D1: Peso por volumen | E1: Precio inicial (valor del 02/01/2015) | F1: Peso por precio | G1: Volumen transaccion inicial (Enero 2015) | H1: Peso por volumen | I1: Precio inicial (Enero 2015) | J1: Peso por precio
A2: Tecnologia | B2: APPLE INC | C2: ='1.1. Datos_Bloomberg'!C3 -> 53204626 | D2: =+C2/SUM($C$2:$C$11) -> 0.33169727 | E2: ='1.1. Datos_Bloomberg'!B3 -> 109.33 | F2: =E2/SUM($E$2:$E$11) -> 0.21070382 | G2: =AVERAGE(INDEX('1.1. Datos_Bloomberg'!$A$3:$BI$22,0,3)) -> 65263181 | H2: =G2/SUM($G$2:$G$11) -> 0.2836262 | I2: =AVERAGE(INDEX('1.1. Datos_Bloomberg'!$A$3:$BI$22,0,2)) -> 110.6415 | J2: =I2/SUM($I$2:$I$11) -> 0.21369903
B3: MICROSOFT CORP | C3: ='1.1. Datos_Bloomberg'!E3 -> 27913852 | D3: =+C3/SUM($C$2:$C$11) -> 0.17402525 | E3: ='1.1. Datos_Bloomberg'!D3 -> 46.76 | F3: =E3/SUM($E$2:$E$11) -> 0.090117175 | G3: =AVERAGE(INDEX('1.1. Datos_Bloomberg'!$A$3:$BI$22,0,5)) -> 45948328 | H3: =G3/SUM($G$2:$G$11) -> 0.19968609 | I3: =AVERAGE(INDEX('1.1. Datos_Bloomberg'!$A$3:$BI$22,0,4)) -> 45.51325 | J3: =I3/SUM($I$2:$I$11) -> 0.087906776
B4: NVIDIA CORP | C4: ='1.1. Datos_Bloomberg'!G3 -> 2842012 | D4: =+C4/SUM($C$2:$C$11) -> 0.017718151 | E4: ='1.1. Datos_Bloomberg'!F3 -> 20.13 | F4: =E4/SUM($E$2:$E$11) -> 0.038795097 | G4: =AVERAGE(INDEX('1.1. Datos_Bloomberg'!$A$3:$BI$22,0,7)) -> 5175473.1 | H4: =G4/SUM($G$2:$G$11) -> 0.022492005 | I4: =AVERAGE(INDEX('1.1. Datos_Bloomberg'!$A$3:$BI$22,0,6)) -> 19.8455 | J4: =I4/SUM($I$2:$I$11) -> 0.038330682
B5: BROADCOM INC | C5: ='1.1. Datos_Bloomberg'!I3 -> 1350045 | D5: =+C5/SUM($C$2:$C$11) -> 0.0084166786 | E5: ='1.1. Datos_Bloomberg'!H3 -> 100.09 | F5: =E5/SUM($E$2:$E$11) -> 0.19289624 | G5: =AVERAGE(INDEX('1.1. Datos_Bloomberg'!$A$3:$BI$22,0,9)) -> 1913603.6 | H5: =G5/SUM($G$2:$G$11) -> 0.0083162991 | I5: =AVERAGE(INDEX('1.1. Datos_Bloomberg'!$A$3:$BI$22,0,8)) -> 103.24975 | J5: =I5/SUM($I$2:$I$11) -> 0.19942221
B6: ORACLE CORP | C6: ='1.1. Datos_Bloomberg'!K3 -> 15070165 | D6: =+C6/SUM($C$2:$C$11) -> 0.093952969 | E6: ='1.1. Datos_Bloomberg'!J3 -> 44.33 | F6: =E6/SUM($E$2:$E$11) -> 0.085434012 | G6: =AVERAGE(INDEX('1.1. Datos_Bloomberg'!$A$3:$BI$22,0,11)) -> 15719375 | H6: =G6/SUM($G$2:$G$11) -> 0.068314577 | I6: =AVERAGE(INDEX('1.1. Datos_Bloomberg'!$A$3:$BI$22,0,10)) -> 43.339 | J6: =I6/SUM($I$2:$I$11) -> 0.083707311
B7: SALESFORCE INC | C7: ='1.1. Datos_Bloomberg'!M3 -> 2801679 | D7: =+C7/SUM($C$2:$C$11) -> 0.017466701 | E7: ='1.1. Datos_Bloomberg'!L3 -> 59.24 | F7: =E7/SUM($E$2:$E$11) -> 0.11416898 | G7: =AVERAGE(INDEX('1.1. Datos_Bloomberg'!$A$3:$BI$22,0,13)) -> 4162153.8 | H7: =G7/SUM($G$2:$G$11) -> 0.018088237 | I7: =AVERAGE(INDEX('1.1. Datos_Bloomberg'!$A$3:$BI$22,0,12)) -> 57.654 | J7: =I7/SUM($I$2:$I$11) -> 0.11135608
B8: ADVANCED MICRO DEVICES | C8: ='1.1. Datos_Bloomberg'!O3 -> 8330255 | D8: =+C8/SUM($C$2:$C$11) -> 0.051933883 | E8: ='1.1. Datos_Bloomberg'!N3 -> 2.69 | F8: =E8/SUM($E$2:$E$11) -> 0.005184243 | G8: =AVERAGE(INDEX('1.1. Datos_Bloomberg'!$A$3:$BI$22,0,15)) -> 22187136 | H8: =G8/SUM($G$2:$G$11) -> 0.096422716 | I8: =AVERAGE(INDEX('1.1. Datos_Bloomberg'!$A$3:$BI$22,0,14)) -> 2.568 | J8: =I8/SUM($I$2:$I$11) -> 0.0049599754
B9: ADOBE INC | C9: ='1.1. Datos_Bloomberg'!Q3 -> 2356405 | D9: =+C9/SUM($C$2:$C$11) -> 0.014690698 | E9: ='1.1. Datos_Bloomberg'!P3 -> 72.34 | F9: =E9/SUM($E$2:$E$11) -> 0.13941566 | G9: =AVERAGE(INDEX('1.1. Datos_Bloomberg'!$A$3:$BI$22,0,17)) -> 2247320.4 | H9: =G9/SUM($G$2:$G$11) -> 0.0097665931 | I9: =AVERAGE(INDEX('1.1. Datos_Bloomberg'!$A$3:$BI$22,0,16)) -> 71.56125 | J9: =I9/SUM($I$2:$I$11) -> 0.13821731
B10: CISCO SYSTEMS INC | C10: ='1.1. Datos_Bloomberg'!S3 -> 22926512 | D10: =+C10/SUM($C$2:$C$11) -> 0.14293233 | E10: ='1.1. Datos_Bloomberg'!R3 -> 27.61 | F10: =E10/SUM($E$2:$E$11) -> 0.053210762 | G10: =AVERAGE(INDEX('1.1. Datos_Bloomberg'!$A$3:$BI$22,0,19)) -> 32991601 | H10: =G10/SUM($G$2:$G$11) -> 0.14337767 | I10: =AVERAGE(INDEX('1.1. Datos_Bloomberg'!$A$3:$BI$22,0,18)) -> 27.56775 | J10: =I10/SUM($I$2:$I$11) -> 0.053245858
B11: INTEL CORP | C11: ='1.1. Datos_Bloomberg'!U3 -> 23605607 | D11: =+C11/SUM($C$2:$C$11) -> 0.14716606 | E11: ='1.1. Datos_Bloomberg'!T3 -> 36.36 | F11: =E11/SUM($E$2:$E$11) -> 0.070074006 | G11: =AVERAGE(INDEX('1.1. Datos_Bloomberg'!$A$3:$BI$22,0,21)) -> 34494621 | H11: =G11/SUM($G$2:$G$11) -> 0.14990961 | I11: =AVERAGE(INDEX('1.1. Datos_Bloomberg'!$A$3:$BI$22,0,20)) -> 35.8045 | J11: =I11/SUM($I$2:$I$11) -> 0.069154766
D12: =SUM(D2:D11) -> 1 | F12: =SUM(F2:F11) -> 1 | H12: =SUM(H2:H11) -> 1 | J12: =SUM(J2:J11) -> 1
A13: Energía | B13: EXXONMOBIL HOLDINGS CORP | C13: ='1.1. Datos_Bloomberg'!W3 -> 10220410 | D13: =+C13/SUM($C$13:$C$22) -> 0.20949128 | E13: ='1.1. Datos_Bloomberg'!V3 -> 92.83 | F13: =E13/SUM($E$13:$E$22) -> 0.10963871 | G13: =AVERAGE(INDEX('1.1. Datos_Bloomberg'!$A$3:$BI$22,0,23)) -> 16340972 | H13: =G13/SUM($G$13:$G$22) -> 0.2032095 | I13: =AVERAGE(INDEX('1.1. Datos_Bloomberg'!$A$3:$BI$22,0,22)) -> 90.5255 | J13: =I13/SUM($I$13:$I$22) -> 0.11396496
B14: CHEVRON CORP | C14: ='1.1. Datos_Bloomberg'!Y3 -> 5907276 | D14: =+C14/SUM($C$13:$C$22) -> 0.12108348 | E14: ='1.1. Datos_Bloomberg'!X3 -> 112.58 | F14: =E14/SUM($E$13:$E$22) -> 0.13296484 | G14: =AVERAGE(INDEX('1.1. Datos_Bloomberg'!$A$3:$BI$22,0,25)) -> 10486018 | H14: =G14/SUM($G$13:$G$22) -> 0.13039974 | I14: =AVERAGE(INDEX('1.1. Datos_Bloomberg'!$A$3:$BI$22,0,24)) -> 106.69 | J14: =I14/SUM($I$13:$I$22) -> 0.13431488
B15: EOG RESOURCES INC | C15: ='1.1. Datos_Bloomberg'!AA3 -> 3463489 | D15: =+C15/SUM($C$13:$C$22) -> 0.070992331 | E15: ='1.1. Datos_Bloomberg'!Z3 -> 92.24 | F15: =E15/SUM($E$13:$E$22) -> 0.10894188 | G15: =AVERAGE(INDEX('1.1. Datos_Bloomberg'!$A$3:$BI$22,0,27)) -> 5396360.3 | H15: =G15/SUM($G$13:$G$22) -> 0.067106881 | I15: =AVERAGE(INDEX('1.1. Datos_Bloomberg'!$A$3:$BI$22,0,26)) -> 88.3845 | J15: =I15/SUM($I$13:$I$22) -> 0.1112696
B16: CONOCOPHILLIPS | C16: ='1.1. Datos_Bloomberg'!AC3 -> 5701787 | D16: =+C16/SUM($C$13:$C$22) -> 0.1168715 | E16: ='1.1. Datos_Bloomberg'!AB3 -> 68.92 | F16: =E16/SUM($E$13:$E$22) -> 0.081399332 | G16: =AVERAGE(INDEX('1.1. Datos_Bloomberg'!$A$3:$BI$22,0,29)) -> 9318217.2 | H16: =G16/SUM($G$13:$G$22) -> 0.11587745 | I16: =AVERAGE(INDEX('1.1. Datos_Bloomberg'!$A$3:$BI$22,0,28)) -> 64.0365 | J16: =I16/SUM($I$13:$I$22) -> 0.080617252
B17: SLB LTD | C17: ='1.1. Datos_Bloomberg'!AE3 -> 5500806 | D17: =+C17/SUM($C$13:$C$22) -> 0.11275192 | E17: ='1.1. Datos_Bloomberg'!AD3 -> 85.67 | F17: =E17/SUM($E$13:$E$22) -> 0.10118225 | G17: =AVERAGE(INDEX('1.1. Datos_Bloomberg'!$A$3:$BI$22,0,31)) -> 9768040.8 | H17: =G17/SUM($G$13:$G$22) -> 0.12147127 | I17: =AVERAGE(INDEX('1.1. Datos_Bloomberg'!$A$3:$BI$22,0,30)) -> 81.4325 | J17: =I17/SUM($I$13:$I$22) -> 0.10251754
B18: TARGA RESOURCES CORP | C18: ='1.1. Datos_Bloomberg'!AG3 -> 471239 | D18: =+C18/SUM($C$13:$C$22) -> 0.0096591486 | E18: ='1.1. Datos_Bloomberg'!AF3 -> 107.06 | F18: =E18/SUM($E$13:$E$22) -> 0.12644533 | G18: =AVERAGE(INDEX('1.1. Datos_Bloomberg'!$A$3:$BI$22,0,33)) -> 740030.25 | H18: =G18/SUM($G$13:$G$22) -> 0.0092027067 | I18: =AVERAGE(INDEX('1.1. Datos_Bloomberg'!$A$3:$BI$22,0,32)) -> 91.609 | J18: =I18/SUM($I$13:$I$22) -> 0.115329
B19: OCCIDENTAL PETROLEUM CORP | C19: ='1.1. Datos_Bloomberg'!AI3 -> 3634610 | D19: =+C19/SUM($C$13:$C$22) -> 0.074499857 | E19: ='1.1. Datos_Bloomberg'!AH3 -> 80.65 | F19: =E19/SUM($E$13:$E$22) -> 0.09525328 | G19: =AVERAGE(INDEX('1.1. Datos_Bloomberg'!$A$3:$BI$22,0,35)) -> 5928659.9 | H19: =G19/SUM($G$13:$G$22) -> 0.073726335 | I19: =AVERAGE(INDEX('1.1. Datos_Bloomberg'!$A$3:$BI$22,0,34)) -> 77.825 | J19: =I19/SUM($I$13:$I$22) -> 0.097975961
B20: PHILLIPS 66 | C20: ='1.1. Datos_Bloomberg'!AK3 -> 2545240 | D20: =+C20/SUM($C$13:$C$22) -> 0.052170664 | E20: ='1.1. Datos_Bloomberg'!AJ3 -> 72.29 | F20: =E20/SUM($E$13:$E$22) -> 0.085379537 | G20: =AVERAGE(INDEX('1.1. Datos_Bloomberg'!$A$3:$BI$22,0,37)) -> 5868461.8 | H20: =G20/SUM($G$13:$G$22) -> 0.072977738 | I20: =AVERAGE(INDEX('1.1. Datos_Bloomberg'!$A$3:$BI$22,0,36)) -> 66.3345 | J20: =I20/SUM($I$13:$I$22) -> 0.083510265
B21: KINDER MORGAN INC | C21: ='1.1. Datos_Bloomberg'!AM3 -> 8662289 | D21: =+C21/SUM($C$13:$C$22) -> 0.17755393 | E21: ='1.1. Datos_Bloomberg'!AL3 -> 42.81 | F21: =E21/SUM($E$13:$E$22) -> 0.050561599 | G21: =AVERAGE(INDEX('1.1. Datos_Bloomberg'!$A$3:$BI$22,0,39)) -> 12548492 | H21: =G21/SUM($G$13:$G$22) -> 0.1560478 | I21: =AVERAGE(INDEX('1.1. Datos_Bloomberg'!$A$3:$BI$22,0,38)) -> 41.641 | J21: =I21/SUM($I$13:$I$22) -> 0.052422962
B22: MARATHON PETROLEUM CORP | C22: ='1.1. Datos_Bloomberg'!AO3 -> 2679659 | D22: =+C22/SUM($C$13:$C$22) -> 0.054925896 | E22: ='1.1. Datos_Bloomberg'!AN3 -> 91.64 | F22: =E22/SUM($E$13:$E$22) -> 0.10823324 | G22: =AVERAGE(INDEX('1.1. Datos_Bloomberg'!$A$3:$BI$22,0,41)) -> 4019159.1 | H22: =G22/SUM($G$13:$G$22) -> 0.049980582 | I22: =AVERAGE(INDEX('1.1. Datos_Bloomberg'!$A$3:$BI$22,0,40)) -> 85.849 | J22: =I22/SUM($I$13:$I$22) -> 0.10807759
D23: =SUM(D13:D22) -> 1 | F23: =SUM(F13:F22) -> 1 | H23: =SUM(H13:H22) -> 1 | J23: =SUM(J13:J22) -> 1
A24: Consumo discrecional | B24: AMAZON.COM INC | C24: ='1.1. Datos_Bloomberg'!AQ3 -> 2788101 | D24: =C24/SUM($C$24:$C$33) -> 0.07799828 | E24: ='1.1. Datos_Bloomberg'!AP3 -> 308.52 | F24: =E24/SUM($E$24:$E$34) -> 0.13744314 | G24: =AVERAGE(INDEX('1.1. Datos_Bloomberg'!$A$3:$BI$22,0,43)) -> 5153097.1 | H24: =G24/SUM($G$24:$G$33) -> 0.099907551 | I24: =AVERAGE(INDEX('1.1. Datos_Bloomberg'!$A$3:$BI$22,0,42)) -> 302.7475 | J24: =I24/SUM($I$24:$I$33) -> 0.1425402
B25: TESLA INC | C25: ='1.1. Datos_Bloomberg'!AS3 -> 4764443 | D25: =C25/SUM($C$24:$C$33) -> 0.13328727 | E25: ='1.1. Datos_Bloomberg'!AR3 -> 219.31 | F25: =E25/SUM($E$24:$E$34) -> 0.097700817 | G25: =AVERAGE(INDEX('1.1. Datos_Bloomberg'!$A$3:$BI$22,0,45)) -> 4510445.2 | H25: =G25/SUM($G$24:$G$33) -> 0.087447904 | I25: =AVERAGE(INDEX('1.1. Datos_Bloomberg'!$A$3:$BI$22,0,44)) -> 203.25525 | J25: =I25/SUM($I$24:$I$33) -> 0.095697051
B26: MCDONALD'S CORP | C26: ='1.1. Datos_Bloomberg'!AU3 -> 6019693 | D26: =C26/SUM($C$24:$C$33) -> 0.1684034 | E26: ='1.1. Datos_Bloomberg'!AT3 -> 93.26 | F26: =E26/SUM($E$24:$E$34) -> 0.041546569 | G26: =AVERAGE(INDEX('1.1. Datos_Bloomberg'!$A$3:$BI$22,0,47)) -> 7638820.3 | H26: =G26/SUM($G$24:$G$33) -> 0.14810042 | I26: =AVERAGE(INDEX('1.1. Datos_Bloomberg'!$A$3:$BI$22,0,46)) -> 91.802 | J26: =I26/SUM($I$24:$I$33) -> 0.043222405
B27: BOOKING HOLDINGS INC | C27: ='1.1. Datos_Bloomberg'!AW3 -> 510013 | D27: =C27/SUM($C$24:$C$33) -> 0.014267825 | E27: ='1.1. Datos_Bloomberg'!AV3 -> 1142.06 | F27: =E27/SUM($E$24:$E$34) -> 0.50877842 | G27: =AVERAGE(INDEX('1.1. Datos_Bloomberg'!$A$3:$BI$22,0,49)) -> 877364.45 | H27: =G27/SUM($G$24:$G$33) -> 0.017010224 | I27: =AVERAGE(INDEX('1.1. Datos_Bloomberg'!$A$3:$BI$22,0,48)) -> 1044.263 | J27: =I27/SUM($I$24:$I$33) -> 0.49166204
B28: HOME DEPOT INC | C28: ='1.1. Datos_Bloomberg'!AY3 -> 4324850 | D28: =C28/SUM($C$24:$C$33) -> 0.12098947 | E28: ='1.1. Datos_Bloomberg'!AX3 -> 103.43 | F28: =E28/SUM($E$24:$E$34) -> 0.046077222 | G28: =AVERAGE(INDEX('1.1. Datos_Bloomberg'!$A$3:$BI$22,0,51)) -> 5491405 | H28: =G28/SUM($G$24:$G$33) -> 0.10646662 | I28: =AVERAGE(INDEX('1.1. Datos_Bloomberg'!$A$3:$BI$22,0,50)) -> 104.205 | J28: =I28/SUM($I$24:$I$33) -> 0.049062011
B29: LOWE'S COS INC | C29: ='1.1. Datos_Bloomberg'!BA3 -> 4213210 | D29: =C29/SUM($C$24:$C$33) -> 0.11786629 | E29: ='1.1. Datos_Bloomberg'!AZ3 -> 67.7 | F29: =E29/SUM($E$24:$E$34) -> 0.030159798 | G29: =AVERAGE(INDEX('1.1. Datos_Bloomberg'!$A$3:$BI$22,0,53)) -> 5647926.9 | H29: =G29/SUM($G$24:$G$33) -> 0.10950124 | I29: =AVERAGE(INDEX('1.1. Datos_Bloomberg'!$A$3:$BI$22,0,52)) -> 68.196 | J29: =I29/SUM($I$24:$I$33) -> 0.03210818
B30: EBAY INC | C30: ='1.1. Datos_Bloomberg'!BC3 -> 5901204 | D30: =C30/SUM($C$24:$C$33) -> 0.16508862 | E30: ='1.1. Datos_Bloomberg'!BB3 -> 56.21 | F30: =E30/SUM($E$24:$E$34) -> 0.025041097 | G30: =AVERAGE(INDEX('1.1. Datos_Bloomberg'!$A$3:$BI$22,0,55)) -> 10249918 | H30: =G30/SUM($G$24:$G$33) -> 0.19872403 | I30: =AVERAGE(INDEX('1.1. Datos_Bloomberg'!$A$3:$BI$22,0,54)) -> 54.874 | J30: =I30/SUM($I$24:$I$33) -> 0.025835889
B31: STARBUCKS CORP | C31: ='1.1. Datos_Bloomberg'!BE3 -> 3453049 | D31: =C31/SUM($C$24:$C$33) -> 0.096600475 | E31: ='1.1. Datos_Bloomberg'!BD3 -> 81.44 | F31: =E31/SUM($E$24:$E$34) -> 0.036280856 | G31: =AVERAGE(INDEX('1.1. Datos_Bloomberg'!$A$3:$BI$22,0,57)) -> 6684001.3 | H31: =G31/SUM($G$24:$G$33) -> 0.12958852 | I31: =AVERAGE(INDEX('1.1. Datos_Bloomberg'!$A$3:$BI$22,0,56)) -> 82.99 | J31: =I31/SUM($I$24:$I$33) -> 0.039073521
B32: MARRIOTT INTERNATIONAL -CL A | C32: ='1.1. Datos_Bloomberg'!BG3 -> 1278232 | D32: =C32/SUM($C$24:$C$33) -> 0.035759069 | E32: ='1.1. Datos_Bloomberg'!BF3 -> 77.75 | F32: =E32/SUM($E$24:$E$34) -> 0.034636991 | G32: =AVERAGE(INDEX('1.1. Datos_Bloomberg'!$A$3:$BI$22,0,59)) -> 2052547.9 | H32: =G32/SUM($G$24:$G$33) -> 0.039794523 | I32: =AVERAGE(INDEX('1.1. Datos_Bloomberg'!$A$3:$BI$22,0,58)) -> 77.1025 | J32: =I32/SUM($I$24:$I$33) -> 0.036301556
B33: NIKE INC -CL B | C33: ='1.1. Datos_Bloomberg'!BI3 -> 2492878 | D33: =C33/SUM($C$24:$C$33) -> 0.069739294 | E33: ='1.1. Datos_Bloomberg'!BH3 -> 95.03 | F33: =E33/SUM($E$24:$E$34) -> 0.04233509 | G33: =AVERAGE(INDEX('1.1. Datos_Bloomberg'!$A$3:$BI$22,0,61)) -> 3273128.4 | H33: =G33/SUM($G$24:$G$33) -> 0.063458971 | I33: =AVERAGE(INDEX('1.1. Datos_Bloomberg'!$A$3:$BI$22,0,60)) -> 94.5095 | J33: =I33/SUM($I$24:$I$33) -> 0.044497156
D34: =SUM(D24:D33) -> 1 | F34: =SUM(F24:F33) -> 1 | H34: =SUM(H24:H33) -> 1 | J34: =SUM(J24:J33) -> 1
C35: Al comparar los pesos por precio con los pesos por volumen, la composición de los tres índices cambia de forma importante. En Tecnología, la regla de volumen concentra el índice en 4 empresas, las cuales son Apple (33,2 %), Microsoft (17,4 %), Intel (14,7 %) y Cisco (14,3 %), mientras que la de precio reparte más el peso y sube a Broadcom de 0,8 % a 19,3 %, a la vez que AMD cae de 5,2 % a 0,5 %. En Energía, Targa pasa de 1,0 % a 12,6 % y Kinder Morgan baja de 17,8 % a 5,1 %, aunque este sigue siendo el índice más equilibrado con ambas reglas. El caso más extremo es Consumo discrecional, puesto que Booking representa solo el 1,4 % por volumen, pero el 50,9 % por precio, porque su acción costaba 1.142 dólares. Los pesos cambian porque el precio por el volumen es el valor negociado. Para mover un monto similar, una acción barata (AMD a cerca de 3 dólares, Cisco a 28) necesita negociar muchas más acciones que una cara (Booking o Broadcom), por eso las dos reglas tienden a ir en direcciones opuestas. Ninguna mide el tamaño económico de la empresa, por un lado el precio por acción depende de cuántas acciones emitió cada compañía y de sus splits, y por otro lado el volumen refleja actividad de negociación, no valor. Para el fondo, la implicación es que la regla de ponderación decide qué empresas "hablan" por el sector. Con pesos por precio, el índice de consumo es en la práctica medio índice de Booking y refleja sobre todo el negocio de viajes. Con pesos por volumen, el de tecnología depende en un tercio de Apple. Por eso el fondo no debería leer ninguno de estos índices como "el sector", sino verificar si sus conclusiones se mantienen con ambas reglas (y con pesos iguales) | G35: En este caso resolvemos el problema de robustez que existia calculando pesos en base al dato de un solo dia, que generaba posibles cambios abruptos en la medida si se cambiaba el valor. Al comparar los pesos por precio con los pesos por volumen, la composición de los índices cambia de forma importante. En Tecnología, el volumen concentra el índice en Apple (28,4 %), Microsoft (20,0 %), Intel (15,0 %) y Cisco (14,3 %), mientras que el precio sube a Broadcom de 0,8 % a 19,9 % y a Adobe de 1,0 % a 13,8 %, y reduce a AMD de 9,6 % a 0,5 %. En Energía, Targa pasa de 0,9 % a 11,5 % y Kinder Morgan baja de 15,6 % a 5,2 %, aunque es el índice más equilibrado con ambas reglas. El caso extremo es consumo discrecional, puesto que Booking pesa 1,7 % por volumen, pero 49,2 % por precio, porque su acción costaba más de 1.000 dólares, mientras eBay cae de 19,9 % a 2,6 %. El índice de consumo es casi medio índice de Booking, mientras que con volumen, el tecnológico depende en más de un cuarto de Apple. Por eso, sus conclusiones solo serán confiables si se mantienen con ambas reglas.

Sheet 2.1 Naturaleza
A1: Punto 2.1 — Naturaleza de los índices
A2: Sector | B2: ¿Qué incluye? | C2: Industrias / tipos de empresa representados | D2: Limitaciones de la selección
A3: Tecnologia | B3: Índice compuesto por 10 empresas del sector tecnológico. Representa principalmente empresas de hardware/computación, software, semiconductores y telecomunicaciones. El universo incluye compañías grandes y conocidas de la industria tecnológica estadounidense. | C3: Computers, Software, Semiconductors y Telecommunications. | D3: La muestra es de solo 10 acciones, por lo que no representa todo el sector. Además, la selección depende de las empresas elegidas y puede estar concentrada en determinadas industrias, países y tamaños empresariales. Por ello, el índice debe interpretarse como una muestra del sector y no como una medida exhaustiva de toda la economía sectorial.
A4: Energía | B4: Índice compuesto por 10 empresas del sector energético. Predominan compañías de petróleo y gas, además de servicios energéticos y transporte por ductos (pipelines). Incluye empresas de Estados Unidos, | C4: Oil&Gas, Oil&Gas Services y Pipelines. | D4: La muestra es de solo 10 acciones, por lo que no representa todo el sector. Además, la selección depende de las empresas elegidas y puede estar concentrada en determinadas industrias, países y tamaños empresariales. Por ello, el índice debe interpretarse como una muestra del sector y no como una medida exhaustiva de toda la economía sectorial.
A5: Consumo discrecional | B5: Índice compuesto por 10 empresas de consumo discrecional. Incluye compañías relacionadas con comercio minorista, internet, restaurantes, viajes/alojamiento, automóviles y prendas de vestir. empresas de Estados Unidos | C5: Internet, Apparel, Retail, Auto Manufacturers y Lodging. | D5: La muestra es de solo 10 acciones, por lo que no representa todo el sector. Además, la selección depende de las empresas elegidas y puede estar concentrada en determinadas industrias, países y tamaños empresariales. Por ello, el índice debe interpretarse como una muestra del sector y no como una medida exhaustiva de toda la economía sectorial.
A7: Datos extraidos de bloomberg
A8: Para el nombre de la empresa se uso la formula | E8: BDP(TICKER;"NAME")
A9: Para el tipo de negocio de la empresa se uso la formula | E9: BDP(TICKER;"INDUSTRY_GROUP")
A10: Para obtener precios de cierre diario y los volúmenes de transacción entre 2015 y 2025 se usaron las siguientes formulas, donde:• Days=T: Incluye solo los días bursátiles o de negociación activos (Trading days = True). • CapChg=N: No ajusta los datos históricos por cambios de capital corporativos automáticos (Capital Changes = No). • CshAdjNormal=N: No ajusta los precios históricos por dividendos normales en efectivo (Cash Adjustment Normal = No). • CshAdjAbnormal=N: No ajusta los precios por dividendos extraordinarios o anormales (Cash Adjustment Abnormal = No). • UseDPDF=N: No utiliza las preferencias predeterminadas de precios y distribución configuradas en el terminal de Bloomberg para acciones corporativas (Use Default Pricing and Distribution Settings = No) | E10: BDH(B1;B2:C2;"01/01/2015";"12/31/2025";"Days=T";"CapChg=N";"CshAdjNormal=N";"CshAdjAbnormal=N";"UseDPDF=N")
E11: BDH(D1;D2:E2;"01/01/2015";"12/31/2025";"Days=T";"Dates=H";"CapChg=N";"CshAdjNormal=N";"CshAdjAbnormal=N";"UseDPDF=N")
A15: Sector | B15: TICKER | C15: Empresa | D15: Tipo de negocio
A16: Tecnologia | B16: AAPL US Equity | C16: APPLE INC | D16: Computers
A17: Tecnologia | B17: MSFT US Equity | C17: MICROSOFT CORP | D17: Software
A18: Tecnologia | B18: NVDA US Equity | C18: NVIDIA CORP | D18: Semiconductors
A19: Tecnologia | B19: AVGO US Equity | C19: BROADCOM INC | D19: Semiconductors
A20: Tecnologia | B20: ORCL US Equity | C20: ORACLE CORP | D20: Software
A21: Tecnologia | B21: CRM US Equity | C21: SALESFORCE INC | D21: Software
A22: Tecnologia | B22: AMD US Equity | C22: ADVANCED MICRO DEVICES | D22: Semiconductors
A23: Tecnologia | B23: ADBE US Equity | C23: ADOBE INC | D23: Software
A24: Tecnologia | B24: CSCO US Equity | C24: CISCO SYSTEMS INC | D24: Telecommunications
A25: Tecnologia | B25: INTC US Equity | C25: INTEL CORP | D25: Semiconductors
A26: Energía | B26: XOM US Equity | C26: EXXONMOBIL HOLDINGS CORP | D26: Oil&Gas
... A45: Consumo discrecional | B45: NKE US Equity | C45: NIKE INC -CL B | D45: Apparel

Sheet 2.2 Retornos
A1: Punto 2.2 — Retornos aritméticos diarios y retornos ponderados
A2: Metodología: | B2: 2.2 Retornos'!L110:L199'2.2 Retornos'!L43'2.2 Retornos'!L43:L57
A4: Retorno diario de cada empresa | B4: 1.1. Datos_Bloomberg'!B4/'1.1. Datos_Bloomberg'!B3-1
A6: Pesos iniciales por volumen — enero de 2015
A7: Sector | B7: Ticker | C7: Empresa | D7: Peso inicial | E7: Fórmula conceptual
A8: Tecnologia | B8: AAPL US Equity | C8: APPLE INC | D8: 0.480399 | E8: Volumen inicial de la acción / volumen inicial total del sector
A9: Tecnologia | B9: MSFT US Equity | C9: MICROSOFT CORP | D9: 0.06301 | E9: Volumen inicial de la acción / volumen inicial total del sector
A10: Tecnologia | B10: NVDA US Equity | C10: NVIDIA CORP | D10: 0.256613 | E10: Volumen inicial de la acción / volumen inicial total del sector
A11: Tecnologia | B11: AVGO US Equity | C11: BROADCOM INC | D11: 0.030475 | E11: Volumen inicial de la acción / volumen inicial total del sector
A12: Tecnologia | B12: ORCL US Equity | C12: ORACLE CORP | D12: 0.034018 | E12: Volumen inicial de la acción / volumen inicial total del sector
A13: Tecnologia | B13: CRM US Equity | C13: SALESFORCE INC | D13: 0.006324 | E13: Volumen inicial de la acción / volumen inicial total del sector
A14: Tecnologia | B14: AMD US Equity | C14: ADVANCED MICRO DEVICES | D14: 0.018804 | E14: Volumen inicial de la acción / volumen inicial total del sector
A15: Tecnologia | B15: ADBE US Equity | C15: ADOBE INC | D15: 0.005319 | E15: Volumen inicial de la acción / volumen inicial total del sector
A16: Tecnologia | B16: CSCO US Equity | C16: CISCO SYSTEMS INC | D16: 0.051752 | E16: Volumen inicial de la acción / volumen inicial total del sector
A17: Tecnologia | B17: INTC US Equity | C17: INTEL CORP | D17: 0.053285 | E17: Volumen inicial de la acción / volumen inicial total del sector
A18: Energía | B18: XOM US Equity | C18: EXXONMOBIL HOLDINGS CORP | D18: 0.174422 | E18: Volumen inicial de la acción / volumen inicial total del sector
A19: Energía | B19: CVX US Equity | C19: CHEVRON CORP | D19: 0.059753 | E19: Volumen inicial de la acción / volumen inicial total del sector
... A37: Consumo discrecional | B37: NKE US Equity | C37: NIKE INC -CL B | D37: 0.050844 | E37: Volumen inicial de la acción / volumen inicial total del sector
A40: Retornos diarios — Tecnologia
A41: Fecha | B41: AAPL US Equity | C41: MSFT US Equity | D41: NVDA US Equity | E41: AVGO US Equity | F41: ORCL US Equity | G41: CRM US Equity | H41: AMD US Equity | I41: ADBE US Equity | J41: CSCO US Equity | K41: INTC US Equity | L41: Retorno índice Tecnologia
A42: 42006 | L42: #VALUE!
A43: 42009 | B43: -0.028172 | C43: -0.009196 | D43: -0.01689 | E43: -0.015986 | F43: -0.016693 | G43: -0.018062 | H43: -0.011152 | I43: -0.004976 | J43: -0.01992 | K43: -0.011276 | L43: {=MMULT(B43:K43,$D$8:$D$17)} -> -0.021484605
A44: 42010 | B44: 9.4e-05 | C44: -0.014677 | D44: -0.030318 | E44: -0.022743 | F44: -0.010323 | G44: -0.016675 | H44: -0.011278 | I44: -0.020144 | J44: -0.00037 | K44: -0.018637 | L44: {=MMULT(B44:K44,$D$8:$D$17)} -> -0.011140785
A45: 42011 | B45: 0.014022 | C45: 0.012705 | D45: -0.002606 | E45: 0.027013 | F45: 0.000232 | G45: -0.00472 | H45: -0.019011 | I45: 0.008223 | J45: 0.009242 | K45: 0.020975 | L45: {=MMULT(B45:K45,$D$8:$D$17)} -> 0.0089514276
A46: 42012 | B46: 0.038422 | C46: 0.029418 | D46: 0.037618 | E46: 0.049975 | F46: 0.006025 | G46: 0.029159 | H46: 0.011628 | I46: 0.025454 | J46: 0.007692 | K46: 0.018601 | L46: {=MMULT(B46:K46,$D$8:$D$17)} -> 0.033620408
A47: 42013 | B47: 0.001072 | C47: -0.008405 | D47: 0.004028 | E47: 0.010695 | F47: -0.000461 | G47: -0.007339 | H47: 0.007663 | I47: -0.014811 | J47: 0.010178 | K47: 0.001908 | L47: {=MMULT(B47:K47,$D$8:$D$17)} -> 0.0019765768
A48: 42016 | B48: -0.024641 | C48: -0.012503 | D48: -0.012538 | E48: -0.016587 | F48: -0.002766 | G48: -0.007393 | H48: 0 | I48: -0.010022 | J48: 0.009356 | K48: -0.004353 | L48: {=MMULT(B48:K48,$D$8:$D$17)} -> -0.01629014
A49: 42017 | B49: 0.008879 | C49: -0.00515 | D49: -0.001524 | E49: -0.005622 | F49: -0.007858 | G49: 0.004157 | H49: 0.011407 | I49: -0.007452 | J49: 0.001783 | K49: -0.002732 | L49: {=MMULT(B49:K49,$D$8:$D$17)} -> 0.0032590872
A50: 42018 | B50: -0.003811 | C50: -0.008628 | D50: 0.004069 | E50: 0.007896 | F50: 0.003028 | G50: -0.01242 | H50: -0.011278 | I50: -0.0085 | J50: -0.006406 | K50: -0.00411 | L50: {=MMULT(B50:K50,$D$8:$D$17)} -> -0.0018730072
A51: 42019 | B51: -0.02714 | C51: -0.010444 | D51: -0.007092 | E51: -0.020021 | F51: -0.009986 | G51: -0.03738 | H51: -0.041825 | I51: 0.004286 | J51: -0.018266 | K51: -0.004402 | L51: {=MMULT(B51:K51,$D$8:$D$17)} -> -0.018645782
A52: 42020 | B52: -0.00777 | C52: 0.016711 | D52: 0.018367 | E52: 0.024674 | F52: 0.020643 | G52: 0.027763 | H52: -0.051587 | I52: 0.020487 | J52: 0.00985 | K52: 0.007184 | L52: {=MMULT(B52:K52,$D$8:$D$17)} -> 0.0036947028
A53: 42024 | B53: 0.025757 | C53: 0.003244 | D53: 0.003006 | E53: 0.010114 | F53: 0.008963 | G53: 0.011476 | H53: -0.062762 | I53: -0.003346 | J53: 0.01409 | K53: -0.009877 | L53: {=MMULT(B53:K53,$D$8:$D$17)} -> 0.013040038
A54: 42025 | B54: 0.007634 | C54: -0.010131 | D54: 0.013986 | E54: 0.004863 | F54: -0.009339 | G54: 0.007331 | H54: 0.09375 | I54: 0.000699 | J54: -0.008194 | K54: 0.010806 | L54: {=MMULT(B54:K54,$D$8:$D$17)} -> 0.0084132029
... A2808: 0 | B2808: -1 | C2808: -1 | D2808: -1 | E2808: -1 | F2808: -1 | G2808: -1 | H2808: -1 | I2808: -1 | J2808: -1 | K2808: -1 | L2808: {=MMULT(B2808:K2808,$D$8:$D$17)} -> -0.999999
A2811: Retornos diarios — Energía
A2812: Fecha | B2812: XOM US Equity | C2812: CVX US Equity | D2812: EOG US Equity | E2812: COP US Equity | F2812: SLB US Equity | G2812: TRGP US Equity | H2812: OXY US Equity | I2812: PSX US Equity | J2812: KMI US Equity | K2812: MPC US Equity | L2812: Retorno índice Energía
A2813: 42006 | L2813: #VALUE!
A2814: 42009 | B2814: -0.027362 | C2814: -0.039972 | D2814: -0.060278 | E2814: -0.047591 | F2814: -0.027081 | G2814: -0.07351 | H2814: -0.037074 | I2814: -0.060451 | J2814: -0.027096 | K2814: -0.027826 | L2814: {=MMULT(B2814:K2814,$D$18:$D$27)} -> -0.041436891
A2815: 42010 | B2815: -0.005316 | C2815: -0.000463 | D2815: -0.028496 | E2815: -0.041286 | F2815: -0.019556 | G2815: -0.031052 | H2815: -0.008499 | I2815: -0.027974 | J2815: -0.019688 | K2815: -0.009878 | L2815: {=MMULT(B2815:K2815,$D$18:$D$27)} -> -0.019494362
A2816: 42011 | B2816: 0.010133 | C2816: -0.000833 | D2816: -0.006294 | E2816: 0.006674 | F2816: -0.000122 | G2816: -0.009468 | H2816: 0.00013 | I2816: 0.004393 | J2816: 0.013226 | K2816: 0.008276 | L2816: {=MMULT(B2816:K2816,$D$18:$D$27)} -> 0.0048608174
...

Sheet 2.3 Gráfico de cajas y bigotes
B19: Dispersión: los tres índices varían de forma parecida. Tecnología es el más disperso (desv. estándar 2,00 %), luego Energía (1,89 %) y Consumo discrecional (1,86 %). Consumo tiene la caja más corta (RIC 1,52 % vs 1,76 % y 1,74 %): en días normales es el más estable.
K20: Métrica | L20: Tecnología | M20: Energía | N20: Consumo discrecional
K21: Observaciones (días) | L21: =COUNT('2.2 Retornos'!$L$43:$L$2807) -> 2765 | M21: =COUNT('2.2 Retornos'!$L$43:$L$2807) -> 2765 | N21: =COUNT('2.2 Retornos'!$L$43:$L$2807) -> 2765
K22: Desviación estándar | L22: =STDEV('2.2 Retornos'!$L$43:$L$2807)*100% -> 0.019971225 | M22: =STDEV('2.2 Retornos'!$L$2814:$L$5578)*100% -> 0.018888458 | N22: =STDEV('2.2 Retornos'!$L$5583:$L$8347)*100% -> 0.018622407
K23: Q1 (percentil 25) | L23: =_xlfn.QUARTILE.EXC('2.2 Retornos'!$L$43:$L$2807,1)*100% -> -0.007187793 | M23: =_xlfn.QUARTILE.EXC('2.2 Retornos'!$L$2814:$L$5578,1)*100% -> -0.0085216595 | N23: =_xlfn.QUARTILE.EXC('2.2 Retornos'!$L$5583:$L$8347,1)*100% -> -0.0064272731
B24: Outliers: los tres tienen casi la misma cantidad, unos 159 días (≈5,7 % de los días). Energía es la más simétrica (83 hacia abajo, 76 hacia arriba); Tecnología (99 vs 60) y Consumo (86 vs 72) tienen más atípicos negativos que positivos. | K24: Q3 (percentil 75) | L24: =_xlfn.QUARTILE.EXC('2.2 Retornos'!$L$43:$L$2807,3)*100% -> 0.010404127 | M24: =_xlfn.QUARTILE.EXC('2.2 Retornos'!$L$2814:$L$5578,3)*100% -> 0.0088995712 | N24: =_xlfn.QUARTILE.EXC('2.2 Retornos'!$L$5583:$L$8347,3)*100% -> 0.0087317974
K25: RIC = Q3 − Q1 (largo de la caja) | L25: =L24-L23 -> 0.01759192 | M25: =M24-M23 -> 0.017421231 | N25: =N24-N23 -> 0.01515907
K26: Límite inferior (Q1 − 1,5·RIC) | L26: =L23-1.5*L25 -> -0.033575673 | M26: =M23-1.5*M25 -> -0.034653505 | N26: =N23-1.5*N25 -> -0.029165879
K27: Límite superior (Q3 + 1,5·RIC) | L27: =L24+1.5*L25 -> 0.036792007 | M27: =M24+1.5*M25 -> 0.035031417 | N27: =N24+1.5*N25 -> 0.031470403
K28: Outliers hacia abajo | L28: =COUNTIF('2.2 Retornos'!$L$43:$L$2807,"<"&L26) -> 99 | M28: =COUNTIF('2.2 Retornos'!$L$2814:$L$5578,"<"&M26) -> 83 | N28: =COUNTIF('2.2 Retornos'!$L$5583:$L$8347,"<"&N26) -> 86
B29: Se distinguen los extremos: peor día de −35,1 % en Tecnología, −21,5 % en Energía y −53,8 % en Consumo. | K29: Outliers hacia arriba | L29: =COUNTIF('2.2 Retornos'!$L$43:$L$2807,">"&L27) -> 60 | M29: =COUNTIF('2.2 Retornos'!$L$2814:$L$5578,">"&M27) -> 76 | N29: =COUNTIF('2.2 Retornos'!$L$5583:$L$8347,">"&N27) -> 72
K30: Total de outliers | L30: =L28+L29 -> 159 | M30: =M28+M29 -> 159 | N30: =N28+N29 -> 158
K31: % de los días que son outliers | L31: =(L30/L21)*100 -> 5.7504521 | M31: =M30/M21*100 -> 5.7504521 | N31: =N30/N21*100 -> 5.7142857
K32: Peor día (mínimo) | L32: =MIN('2.2 Retornos'!$L$43:$L$2807) -> -0.35117624 | M32: =MIN('2.2 Retornos'!$L$2814:$L$5578) -> -0.21451943 | N32: =MIN('2.2 Retornos'!$L$5583:$L$8347) -> -0.53847531
K33: Mejor día (máximo) | L33: =MAX('2.2 Retornos'!$L$43:$L$2807) -> 0.15812044 | M33: =MAX('2.2 Retornos'!$L$2814:$L$5578) -> 0.16132225 | N33: =MAX('2.2 Retornos'!$L$5583:$L$8347) -> 0.10437274

Sheet 2.4 histogramas

Sheet 2.5 Graficas
B1: base 100 tegnologia | C1: base 100 energia | D1: base 100 consumo
A2: 42009 | B2: 100 | C2: 100 | D2: 100
A3: 42010 | B3: =B2*(1+'2.2 Retornos'!L43) -> 97.851539 | C3: =C2*(1+'2.2 Retornos'!L2814) -> 95.856311 | D3: =D2*(1+'2.2 Retornos'!L5583) -> 97.845821
A4: 42011 | B4: =B3*(1+'2.2 Retornos'!L44) -> 96.761397 | C4: =C3*(1+'2.2 Retornos'!L2815) -> 93.987653 | D4: =D3*(1+'2.2 Retornos'!L5584) -> 96.199954
A5: 42012 | B5: =B4*(1+'2.2 Retornos'!L45) -> 97.627549 | C5: =C4*(1+'2.2 Retornos'!L2816) -> 94.44451 | D5: =D4*(1+'2.2 Retornos'!L5585) -> 97.174791
A6: 42013 | B6: =B5*(1+'2.2 Retornos'!L46) -> 100.90983 | C6: =C5*(1+'2.2 Retornos'!L2817) -> 96.75545 | D6: =D5*(1+'2.2 Retornos'!L5586) -> 98.238275
A7: 42016 | B7: =B6*(1+'2.2 Retornos'!L47) -> 101.10928 | C7: =C6*(1+'2.2 Retornos'!L2818) -> 95.727956 | D7: =D6*(1+'2.2 Retornos'!L5587) -> 96.699222
A8: 42017 | B8: =B7*(1+'2.2 Retornos'!L48) -> 99.462199 | C8: =C7*(1+'2.2 Retornos'!L2819) -> 92.961923 | D8: =D7*(1+'2.2 Retornos'!L5588) -> 95.462213
A9: 42018 | B9: =B8*(1+'2.2 Retornos'!L49) -> 99.786355 | C9: =C8*(1+'2.2 Retornos'!L2820) -> 91.519157 | D9: =D8*(1+'2.2 Retornos'!L5589) -> 96.026429
A10: 42019 | B10: =B9*(1+'2.2 Retornos'!L50) -> 99.599454 | C10: =C9*(1+'2.2 Retornos'!L2821) -> 91.195637 | D10: =D9*(1+'2.2 Retornos'!L5590) -> 95.34151
A11: 42020 | B11: =B10*(1+'2.2 Retornos'!L51) -> 97.742344 | C11: =C10*(1+'2.2 Retornos'!L2822) -> 90.334868 | D11: =D10*(1+'2.2 Retornos'!L5591) -> 93.421848
A12: 42024 | B12: =B11*(1+'2.2 Retornos'!L52) -> 98.103473 | C12: =C11*(1+'2.2 Retornos'!L2823) -> 93.044496 | D12: =D11*(1+'2.2 Retornos'!L5592) -> 94.523253
A13: 42025 | B13: =B12*(1+'2.2 Retornos'!L53) -> 99.382746 | C13: =C12*(1+'2.2 Retornos'!L2824) -> 94.06339 | D13: =D12*(1+'2.2 Retornos'!L5593) -> 94.49281
A14: 42026 | B14: =B13*(1+'2.2 Retornos'!L54) -> 100.21887 | C14: =C13*(1+'2.2 Retornos'!L2825) -> 95.900778 | D14: =D13*(1+'2.2 Retornos'!L5594) -> 96.157171
... A2766: 46022 | B2766: =B2765*(1+'2.2 Retornos'!L2806) -> 1112.9164 | C2766: =C2765*(1+'2.2 Retornos'!L5577) -> 127.998 | D2766: =D2765*(1+'2.2 Retornos'!L8346) -> 392.84559

Sheet 3.2 Intervalos de confianza
A2: Nivel de significancia (α) | B2: 0.05
A3: Nivel de confianza | B3: 0.95
A5: Índice | B5: n (días) | C5: Promedio diario | D5: Desv. estándar | E5: Margen (CONFIDENCE.T) | F5: Límite inferior | G5: Límite superior | H5: ¿El IC incluye 0?
A6: Tecnología | B6: 2765 | C6: 0.001079 | D6: 0.019971 | E6: 0.000745 | F6: 0.000334 | G6: 0.001824 | H6: No
A7: Energía | B7: 2765 | C7: 0.000267 | D7: 0.018888 | E7: 0.000704 | F7: -0.000437 | G7: 0.000972 | H7: Sí
A8: Consumo discrecional | B8: 2765 | C8: 0.000699 | D8: 0.018622 | E8: 0.000694 | F8: 4e-06 | G8: 0.001393 | H8: No
A11: Índice | B11: Fecha | C11: Retorno del índice | D11: Causa probable
A12: Tecnología | B12: 44074 | C12: -0.3512 | D12: AAPL: split 4 por 1
A13: Tecnología | B13: 44397 | C13: -0.1778 | D13: NVDA: split 4 por 1
A14: Tecnología | B14: 45453 | C14: -0.2396 | D14: NVDA: split 10 por 1
A15: Tecnología | B15: 45488 | C15: -0.0215 | D15: AVGO: split 10 por 1
A16: Consumo discrecional | B16: 42103 | C16: -0.0328 | D16: SBUX: split 2 por 1
A17: Consumo discrecional | B17: 42205 | C17: -0.0242 | D17: EBAY: escisión de PayPal
A18: Consumo discrecional | B18: 42362 | C18: -0.0277 | D18: NKE: split 2 por 1
A19: Consumo discrecional | B19: 44718 | C19: -0.5385 | D19: AMZN: split 20 por 1
A22: Índice | B22: n (días) | C22: Promedio diario | D22: Desv. estándar | E22: Margen (CONFIDENCE.T) | F22: Límite inferior | G22: Límite superior | H22: ¿El IC incluye 0?
A23: Tecnología (sin 4 días) | B23: 2761 | C23: 0.001367 | D23: 0.017934 | E23: 0.000669 | F23: 0.000697 | G23: 0.002036 | H23: No
A24: Energía (sin cambios) | B24: 2765 | C24: 0.000267 | D24: 0.018888 | E24: 0.000704 | F24: -0.000437 | G24: 0.000972 | H24: Sí
A25: Consumo discrecional (sin 4 días) | B25: 2761 | C25: 0.000925 | D25: 0.015524 | E25: 0.000579 | F25: 0.000346 | G25: 0.001505 | H25: No

Sheet 3.3 comparativa 2015-2025
A1: TEGNOLOGIA | J1: DICRECIONAL | S1: ENERGIA
A2: Año | B2: Promedio retornos | C2: Desviacion estandar | D2: N (observaciones) | E2: Margen de error (95%) | F2: Limite inferior | G2: Limite superior | J2: Año | K2: Promedio retornos | L2: Desviacion estandar | M2: N (observaciones) | N2: Margen de error (95%) | O2: Limite inferior | P2: Limite superior | S2: Año | T2: Promedio retornos | U2: Desviacion estandar | V2: N (observaciones) | W2: Margen de error (95%) | X2: Limite inferior | Y2: Limite superior
A3: 2015 | B3: =AVERAGE('2.2 Retornos'!L43:L293) -> 0.00067162167 | C3: =_xlfn.STDEV.S('2.2 Retornos'!L43:L293) -> 0.014342644 | D3: =COUNT('2.2 Retornos'!L43:L293) -> 251 | E3: =_xlfn.CONFIDENCE.T(0.05, C3, D3) -> 0.0017829863 | F3: =B3-E3 -> -0.0011113646 | G3: =B3+E3 -> 0.002454608 | J3: 2015 | K3: =AVERAGE('2.2 Retornos'!L5584:L5833) -> 0.0020084284 | L3: =_xlfn.STDEV.S('2.2 Retornos'!L5584:L5833) -> 0.015522575 | M3: =COUNT('2.2 Retornos'!L5584:L5833) -> 250 | N3: =_xlfn.CONFIDENCE.T(0.05, L3, M3) -> 0.001933561 | O3: =K3-N3 -> 7.4867439e-05 | P3: =K3+N3 -> 0.0039419893 | S3: 2015 | T3: =AVERAGE('2.2 Retornos'!L2814:L3064) -> -0.00095280394 | U3: =_xlfn.STDEV.S('2.2 Retornos'!L2814:L3064) -> 0.014891276 | V3: =COUNT('2.2 Retornos'!L2814:L3064) -> 251 | W3: =_xlfn.CONFIDENCE.T(0.05, U3, V3) -> 0.0018511886 | X3: =T3-W3 -> -0.0028039926 | Y3: =T3+W3 -> 0.00089838468
A4: 2025 | B4: =AVERAGE('2.2 Retornos'!L2553:L2807) -> 0.0010415526 | C4: =_xlfn.STDEV.S('2.2 Retornos'!L2553:L2807) -> 0.0189441 | D4: =COUNT('2.2 Retornos'!L2553:L2807) -> 255 | E4: =_xlfn.CONFIDENCE.T(0.05, C4, D4) -> 0.0023362873 | F4: =B4-E4 -> -0.0012947346 | G4: =B4+E4 -> 0.0033778399 | J4: 2025 | K4: =AVERAGE('2.2 Retornos'!L8098:L8347) -> 0.00040312881 | L4: =_xlfn.STDEV.S('2.2 Retornos'!L8098:L8347) -> 0.015925557 | M4: =COUNT('2.2 Retornos'!L8098:L8347) -> 250 | N4: =_xlfn.CONFIDENCE.T(0.05, L4, M4) -> 0.0019837582 | O4: =K4-N4 -> -0.0015806294 | P4: =K4+N4 -> 0.002386887 | S4: 2025 | T4: =AVERAGE('2.2 Retornos'!L5329:L5578) -> 0.00026302286 | U4: =_xlfn.STDEV.S('2.2 Retornos'!L5329:L5578) -> 0.016315889 | V4: =COUNT('2.2 Retornos'!L5329:L5578) -> 250 | W4: =_xlfn.CONFIDENCE.T(0.05, U4, V4) -> 0.0020323797 | X4: =T4-W4 -> -0.0017693569 | Y4: =T4+W4 -> 0.0022954026

Sheet 3.4 Interpretación de resultado
A2: A. Promedio y desviación estándar diarios por año
A3: Año | B3: Tecnología — promedio | C3: Tecnología — desv. est. | D3: Energía — promedio | E3: Energía — desv. est. | F3: Consumo — promedio | G3: Consumo — desv. est. | H3: Días del año
A4: 2015 | B4: 0.00067 | C4: 0.01434 | D4: -0.00095 | E4: 0.01489 | F4: 0.00191 | G4: 0.01556 | H4: 251
A5: 2016 | B5: 0.00178 | C5: 0.01407 | D5: 0.00085 | E5: 0.01524 | F5: 0.00043 | G5: 0.01369 | H5: 252
A6: 2017 | B6: 0.00174 | C6: 0.01118 | D6: 6e-05 | E6: 0.00782 | F6: 0.00146 | G6: 0.00866 | H6: 251
A7: 2018 | B7: -0.00013 | C7: 0.01805 | D7: -0.00062 | E7: 0.01355 | F7: 0.00075 | G7: 0.01657 | H7: 251
A8: 2019 | B8: 0.00226 | C8: 0.01569 | D8: 0.00047 | E8: 0.01177 | F8: 0.00096 | G8: 0.01087 | H8: 252
A9: 2020 | B9: 0.00113 | C9: 0.0359 | D9: -0.001 | E9: 0.03994 | F9: 0.00195 | G9: 0.0206 | H9: 253
A10: 2021 | B10: 0.00114 | C10: 0.01904 | D10: 0.00152 | E10: 0.02024 | F10: 0.0005 | G10: 0.01161 | H10: 252
A11: 2022 | B11: -0.00132 | C11: 0.02453 | D11: 0.00213 | E11: 0.02225 | F11: -0.00376 | G11: 0.04165 | H11: 251
A12: 2023 | B12: 0.00269 | C12: 0.01447 | D12: 0.0002 | E12: 0.01396 | F12: 0.00189 | G12: 0.01443 | H12: 250
A13: 2024 | B13: 0.00075 | C13: 0.02139 | D13: 3e-05 | E13: 0.01103 | F13: 0.00119 | G13: 0.0123 | H13: 252
A14: 2025 | B14: 0.00115 | C14: 0.01907 | D14: 0.00026 | E14: 0.01632 | F14: 0.0004 | G14: 0.01593 | H14: 250
A17: B. Comparación 2015 vs 2025
A18: Índice | B18: Promedio 2015 | C18: Promedio 2025 | D18: IC 95 % 2015 — inferior | E18: IC 95 % 2015 — superior | F18: IC 95 % 2025 — inferior | G18: IC 95 % 2025 — superior | H18: ¿Los IC se traslapan? | I18: Desv. est. 2015 | J18: Desv. est. 2025 | K18: Razón 2025 / 2015
A19: Tecnología | B19: 0.00067 | C19: 0.00115 | D19: -0.00111 | E19: 0.00245 | F19: -0.00122 | G19: 0.00353 | H19: Sí | I19: 0.01434 | J19: 0.01907 | K19: 1.33
A20: Energía | B20: -0.00095 | C20: 0.00026 | D20: -0.0028 | E20: 0.0009 | F20: -0.00177 | G20: 0.0023 | H20: Sí | I20: 0.01489 | J20: 0.01632 | K20: 1.1
A21: Consumo discrecional | B21: 0.00191 | C21: 0.0004 | D21: -2e-05 | E21: 0.00385 | F21: -0.00158 | G21: 0.00239 | H21: Sí | I21: 0.01556 | J21: 0.01593 | K21: 1.02
A24: 1. ¿Hay evidencia de un cambio notable entre 2015 y 2025? En el nivel de retorno, no. Los promedios diarios de 2015 y 2025 son pequeños (entre −0,10 % y +0,19 %) y, en los tres índices, los IC al 95 % de ambos años se traslapan ampliamente. En la dispersión, el cambio es moderado y no concluyente: la desviación estándar de Tecnología sube de 1,43 % a 1,91 % (×1,33), la de Energía de 1,49 % a 1,63 % (×1,10) y la de Consumo casi no cambia (1,56 % → 1,59 %).
A30: 2. Qué cambió en retornos o dispersión dentro de la década. El cambio notable no está entre los extremos sino en el medio: en 2020 la desviación estándar diaria fue 3,59 % en Tecnología y 3,99 % en Energía, unas 2,5 veces la de 2015, y en Energía siguió alta en 2021–2022 (2,0–2,2 %) antes de volver a 1,1–1,4 % en 2023–2024. Consumo muestra un pico en 2022 (4,17 %), pero viene de un solo día (AMZN, 06-jun-2022, split sin ajustar); sin ese día su desviación de 2022 baja de 4,17 % a 2,43 %, en línea con Tecnología (2,45 %) ese año. Los retornos promedio anuales cambian de signo de un año a otro sin tendencia clara.
A36: 3. Qué podría ser relevante para el fondo. (a) Riesgo: la desviación estándar subestima el riesgo de cola; la curtosis (Energía 13,4 incluso con datos limpios) indica que los días extremos son mucho más frecuentes que en una normal, así que conviene medir pérdidas con VaR/ES históricos o escenarios y no solo con la volatilidad. (b) Retorno esperado: los IC de los promedios diarios son estrechos pero la media es pequeña frente al ruido; (c) Diversificación: el 12 y el 16 de marzo de 2020 los tres índices figuran entre sus peores caídas; en episodios de estrés estos sectores cayeron juntos, así que combinarlos dio poca protección. (d) Concentración: con pesos fijos de enero de 2015 por volumen, Tecnología depende de AAPL (48 %) y NVDA (26 %) y Consumo de AMZN (57 %); el 'índice' se parece mucho a esas acciones, y los pesos de 2015 ya no reflejan el peso actual.
A44: 4. Qué muestran los datos y qué no (COVID). Los datos muestran hechos descriptivos: en marzo de 2020 hubo caídas diarias grandes y simultáneas en los tres índices, y 2020 fue el año de mayor dispersión en Tecnología y Energía. El libro solo contiene precios y volúmenes; no incluye ninguna variable sobre la pandemia, los contagios, las cuarentenas ni la política económica, así que no permite atribuir esos movimientos al COVID.

Sheet 3.5 Recomendación de inversión
A1: Primero a partir de la evidencia de los tres índices, recomendamos priorizar el seguimiento del sector Tecnología, mantener Consumo discrecional bajo observación y mantener una posición más precavido frente al sector Energía. Esta recomendación no implica que un sector sea necesariamente mejor que otro, sino que refleja las características observadas en los datos de 2015–2025. 1. En el sector Tecnología se presenta un comportamiento favorable en términos de retorno promedio. Su retorno diario promedio fue de 0,067 % en 2015 y de aproximadamente 0,115 % en 2025. Además, tuvo retornos promedio positivos en la mayoría de los años analizados y alcanzó 0,269 % en 2023. Sin embargo, su volatilidad aumentó: la desviación estándar pasó de 1,43 % en 2015 a 1,91 % en 2025, y en 2020 llegó a 3,59 %. También presenta una elevada concentración, ya que el índice depende principalmente de Apple y NVIDIA. Por estas razones, sería un sector para priorizar en el seguimiento, pero acompañado de controles de riesgo y concentración. 2. Ahora bien en el Consumo discrecional se mostró retornos positivos durante buena parte del periodo, aunque su promedio diario pasó de aproximadamente 0,191 % en 2015 a 0,040 % en 2025. Su volatilidad se mantuvo relativamente estable entre ambos años, 1,56 % frente a 1,59 %, por lo que el cambio en el riesgo fue menor que en Tecnología y Energía. Sin embargo, presentó valores extremos importantes, especialmente en 2022, cuando la desviación estándar llegó a 4,17 %. Este resultado estuvo influido por un movimiento asociado a Amazon que requiere un ajuste por split. Por ello, recomendamos mantener este sector bajo observación . 3. Por último en el secto de Energía se presenta una situación diferente. En 2015 tuvo un retorno promedio diario negativo de aproximadamente −0,095 %, mientras que en 2025 fue positivo, pero reducido, cercano a 0,026 %. Su volatilidad pasó de 1,49 % a 1,63 % y alcanzó niveles especialmente altos durante 2020, de 3,99 %, y 2021–2022. Además, registró valores extremos, incluyendo una caída diaria cercana al 21,5 % en marzo de 2020. Esto muestra una mayor exposición a episodios de estrés del mercado. Por ello, recomendamos mantener una postura cautelosa frente a este índice y no basar una decisión únicamente en su retorno promedio. En la comparación entre 2015 y 2025, los intervalos de confianza de los tres sectores se sobreponen, por lo que no existe evidencia estadística suficiente en este análisis para afirmar que alguno haya experimentado un cambio significativo en su retorno promedio. Además, los tres sectores presentaron movimientos negativos importantes durante episodios de estrés, lo que indica que su combinación no necesariamente proporciona una protección completa mediante diversificación. Frente a la Cautela metodológica esta recomendación tiene un alcance limitado porque los índices se construyen con solamente 10 empresas por sector y utilizan pesos iniciales de enero de 2015. Además, existen problemas de ajustes por splits que pueden afectar algunos retornos y valores extremos. Los datos tampoco permiten atribuir directamente los cambios observados al COVID-19, ya que no contienen variables que permitan establecer causalidad. Antes de utilizar los índices para una decisión real de inversión sería necesario ajustar los precios, revisar los datos extremos, actualizar las ponderaciones y complementar el análisis con otras medidas de riesgo, como VaR o Expected Shortfall.
